Traceback (most recent call last):
  File "/opt/jupyterhub/lib/python3.8/site-packages/jupyter_cache/executors/utils.py", line 51, in single_nb_execution
    executenb(
  File "/opt/jupyterhub/lib/python3.8/site-packages/nbclient/client.py", line 1087, in execute
    return NotebookClient(nb=nb, resources=resources, km=km, **kwargs).execute()
  File "/opt/jupyterhub/lib/python3.8/site-packages/nbclient/util.py", line 74, in wrapped
    return just_run(coro(*args, **kwargs))
  File "/opt/jupyterhub/lib/python3.8/site-packages/nbclient/util.py", line 53, in just_run
    return loop.run_until_complete(coro)
  File "/usr/lib/python3.8/asyncio/base_events.py", line 616, in run_until_complete
    return future.result()
  File "/opt/jupyterhub/lib/python3.8/site-packages/nbclient/client.py", line 540, in async_execute
    await self.async_execute_cell(
  File "/opt/jupyterhub/lib/python3.8/site-packages/nbclient/client.py", line 832, in async_execute_cell
    self._check_raise_for_error(cell, exec_reply)
  File "/opt/jupyterhub/lib/python3.8/site-packages/nbclient/client.py", line 740, in _check_raise_for_error
    raise CellExecutionError.from_cell_and_msg(cell, exec_reply['content'])
nbclient.exceptions.CellExecutionError: An error occurred while executing the following cell:
------------------
#### Build the Plot #####
# import matplotlib # might need to activate this line on your computer
from matplotlib import pyplot
fig, ax = matplotlib.pyplot.subplots()
CS = ax.contour(xlist, ylist, zlist, levels = 7)
ax.clabel(CS, inline=2, fontsize=10)
ax.set_title('Contour Plot from Gridded Data File');
################################
------------------

[0;31m---------------------------------------------------------------------------[0m
[0;31mNameError[0m                                 Traceback (most recent call last)
[0;32m<ipython-input-8-c27e9487a373>[0m in [0;36m<module>[0;34m[0m
[1;32m      2[0m [0;31m# import matplotlib # might need to activate this line on your computer[0m[0;34m[0m[0;34m[0m[0;34m[0m[0m
[1;32m      3[0m [0;32mfrom[0m [0mmatplotlib[0m [0;32mimport[0m [0mpyplot[0m[0;34m[0m[0;34m[0m[0m
[0;32m----> 4[0;31m [0mfig[0m[0;34m,[0m [0max[0m [0;34m=[0m [0mmatplotlib[0m[0;34m.[0m[0mpyplot[0m[0;34m.[0m[0msubplots[0m[0;34m([0m[0;34m)[0m[0;34m[0m[0;34m[0m[0m
[0m[1;32m      5[0m [0mCS[0m [0;34m=[0m [0max[0m[0;34m.[0m[0mcontour[0m[0;34m([0m[0mxlist[0m[0;34m,[0m [0mylist[0m[0;34m,[0m [0mzlist[0m[0;34m,[0m [0mlevels[0m [0;34m=[0m [0;36m7[0m[0;34m)[0m[0;34m[0m[0;34m[0m[0m
[1;32m      6[0m [0max[0m[0;34m.[0m[0mclabel[0m[0;34m([0m[0mCS[0m[0;34m,[0m [0minline[0m[0;34m=[0m[0;36m2[0m[0;34m,[0m [0mfontsize[0m[0;34m=[0m[0;36m10[0m[0;34m)[0m[0;34m[0m[0;34m[0m[0m

[0;31mNameError[0m: name 'matplotlib' is not defined
NameError: name 'matplotlib' is not defined

