Traceback (most recent call last):
  File "/opt/jupyterhub/lib/python3.8/site-packages/jupyter_cache/executors/utils.py", line 51, in single_nb_execution
    executenb(
  File "/opt/jupyterhub/lib/python3.8/site-packages/nbclient/client.py", line 1087, in execute
    return NotebookClient(nb=nb, resources=resources, km=km, **kwargs).execute()
  File "/opt/jupyterhub/lib/python3.8/site-packages/nbclient/util.py", line 74, in wrapped
    return just_run(coro(*args, **kwargs))
  File "/opt/jupyterhub/lib/python3.8/site-packages/nbclient/util.py", line 53, in just_run
    return loop.run_until_complete(coro)
  File "/usr/lib/python3.8/asyncio/base_events.py", line 616, in run_until_complete
    return future.result()
  File "/opt/jupyterhub/lib/python3.8/site-packages/nbclient/client.py", line 540, in async_execute
    await self.async_execute_cell(
  File "/opt/jupyterhub/lib/python3.8/site-packages/nbclient/client.py", line 832, in async_execute_cell
    self._check_raise_for_error(cell, exec_reply)
  File "/opt/jupyterhub/lib/python3.8/site-packages/nbclient/client.py", line 740, in _check_raise_for_error
    raise CellExecutionError.from_cell_and_msg(cell, exec_reply['content'])
nbclient.exceptions.CellExecutionError: An error occurred while executing the following cell:
------------------
# Newton-Raphson
for iteration in range(10):
    myfunc = func(xguess[0],xguess[1])
    testf = vdotv(myfunc,myfunc,2)
    if testf <= tolerancef :
        print("f(x) close to zero\n test value : ", testf)
        break
    myjacob=jacob(xguess[0],xguess[1])
    deltax=linearsolver(myjacob,myfunc)
    testx = vdotv(deltax,deltax,2)
    if testx <= tolerancex :
        print("solution change small\n test value : ", testx)
        break
    xguess=vvsub(xguess,deltax,2)
##    print("iteration : ",iteration)
##    writeV(xguess,2,"Current X vector ")
##    writeV(myfunc,2,"Current FUNC vector ")
print("Exiting Iteration : ",iteration)
writeV(xguess,2,"Exiting X vector ")
writeV(myfunc,2,"Exiting FUNC vector ")
------------------

[0;31m---------------------------------------------------------------------------[0m
[0;31mNameError[0m                                 Traceback (most recent call last)
[0;32m<ipython-input-2-e4a405609721>[0m in [0;36m<module>[0;34m[0m
[1;32m      1[0m [0;31m# Newton-Raphson[0m[0;34m[0m[0;34m[0m[0;34m[0m[0m
[1;32m      2[0m [0;32mfor[0m [0miteration[0m [0;32min[0m [0mrange[0m[0;34m([0m[0;36m10[0m[0;34m)[0m[0;34m:[0m[0;34m[0m[0;34m[0m[0m
[0;32m----> 3[0;31m     [0mmyfunc[0m [0;34m=[0m [0mfunc[0m[0;34m([0m[0mxguess[0m[0;34m[[0m[0;36m0[0m[0;34m][0m[0;34m,[0m[0mxguess[0m[0;34m[[0m[0;36m1[0m[0;34m][0m[0;34m)[0m[0;34m[0m[0;34m[0m[0m
[0m[1;32m      4[0m     [0mtestf[0m [0;34m=[0m [0mvdotv[0m[0;34m([0m[0mmyfunc[0m[0;34m,[0m[0mmyfunc[0m[0;34m,[0m[0;36m2[0m[0;34m)[0m[0;34m[0m[0;34m[0m[0m
[1;32m      5[0m     [0;32mif[0m [0mtestf[0m [0;34m<=[0m [0mtolerancef[0m [0;34m:[0m[0;34m[0m[0;34m[0m[0m

[0;31mNameError[0m: name 'xguess' is not defined
NameError: name 'xguess' is not defined

